Process EmbeddingGenerator:
Traceback (most recent call last):
  File "/usr/lib/python3.8/multiprocessing/process.py", line 315, in _bootstrap
    self.run()
  File "/home/usuario/Reinforcement Learning/API/threaded_elements_handler.py", line 31, in run
    mp.Process.run(self)
  File "/usr/lib/python3.8/multiprocessing/process.py", line 108, in run
    self._target(*self._args, **self._kwargs)
  File "/home/usuario/Reinforcement Learning/model/data/generator/generate_trans_embeddings.py", line 96, in generate_embedding
    original_stdout = sys.stdout
NameError: name 'sys' is not defined
Process EmbeddingGenerator:
Traceback (most recent call last):
  File "/usr/lib/python3.8/multiprocessing/process.py", line 315, in _bootstrap
    self.run()
  File "/home/usuario/Reinforcement Learning/API/threaded_elements_handler.py", line 31, in run
    mp.Process.run(self)
  File "/usr/lib/python3.8/multiprocessing/process.py", line 108, in run
    self._target(*self._args, **self._kwargs)
  File "/home/usuario/Reinforcement Learning/model/data/generator/generate_trans_embeddings.py", line 96, in generate_embedding
    original_stdout = sys.stdout
NameError: name 'sys' is not defined
Process EmbeddingGenerator:
Traceback (most recent call last):
  File "/usr/lib/python3.8/multiprocessing/process.py", line 315, in _bootstrap
    self.run()
  File "/home/usuario/Reinforcement Learning/API/threaded_elements_handler.py", line 31, in run
    mp.Process.run(self)
  File "/usr/lib/python3.8/multiprocessing/process.py", line 108, in run
    self._target(*self._args, **self._kwargs)
  File "/home/usuario/Reinforcement Learning/model/data/generator/generate_trans_embeddings.py", line 95, in generate_embedding
    original_stdout = sys.stdout
NameError: name 'sys' is not defined
Process EmbeddingGenerator:
Traceback (most recent call last):
  File "/usr/lib/python3.8/multiprocessing/process.py", line 315, in _bootstrap
    self.run()
  File "/home/usuario/Reinforcement Learning/API/threaded_elements_handler.py", line 31, in run
    mp.Process.run(self)
  File "/usr/lib/python3.8/multiprocessing/process.py", line 108, in run
    self._target(*self._args, **self._kwargs)
  File "/home/usuario/Reinforcement Learning/model/data/generator/generate_trans_embeddings.py", line 95, in generate_embedding
    original_stdout = sys.stdout
NameError: name 'sys' is not defined
Process EmbeddingGenerator:
Traceback (most recent call last):
  File "/home/usuario/Reinforcement Learning/model/data/generator/generate_trans_embeddings.py", line 95, in generate_embedding
    original_stdout = sys.stdout
NameError: name 'sys' is not defined

During handling of the above exception, another exception occurred:

Traceback (most recent call last):
  File "/usr/lib/python3.8/multiprocessing/process.py", line 315, in _bootstrap
    self.run()
  File "/home/usuario/Reinforcement Learning/API/threaded_elements_handler.py", line 31, in run
    mp.Process.run(self)
  File "/usr/lib/python3.8/multiprocessing/process.py", line 108, in run
    self._target(*self._args, **self._kwargs)
  File "/home/usuario/Reinforcement Learning/model/data/generator/generate_trans_embeddings.py", line 98, in generate_embedding
    raise Exception("THIS HAS FAILED.")
Exception: THIS HAS FAILED.
Process EmbeddingGenerator:
Traceback (most recent call last):
  File "/home/usuario/Reinforcement Learning/model/data/generator/generate_trans_embeddings.py", line 95, in generate_embedding
    original_stdout = sys.stdout
NameError: name 'sys' is not defined

During handling of the above exception, another exception occurred:

Traceback (most recent call last):
  File "/usr/lib/python3.8/multiprocessing/process.py", line 315, in _bootstrap
    self.run()
  File "/home/usuario/Reinforcement Learning/API/threaded_elements_handler.py", line 31, in run
    mp.Process.run(self)
  File "/usr/lib/python3.8/multiprocessing/process.py", line 108, in run
    self._target(*self._args, **self._kwargs)
  File "/home/usuario/Reinforcement Learning/model/data/generator/generate_trans_embeddings.py", line 98, in generate_embedding
    raise Exception("THIS HAS FAILED.")
Exception: THIS HAS FAILED.
